Exception in thread Patcher:
Traceback (most recent call last):
  File "threading.pyc", line 551, in __bootstrap_inner
  File "threading.pyc", line 504, in run
  File "Patcher.pyc", line 55, in Patch
  File "ManagedFile.pyc", line 49, in update
  File "ManagedFile.pyc", line 84, in obtainFresh
ValueError: list.remove(x): x not in list

Exception in thread Patcher:
Traceback (most recent call last):
  File "threading.pyc", line 551, in __bootstrap_inner
  File "threading.pyc", line 504, in run
  File "Patcher.pyc", line 55, in Patch
  File "ManagedFile.pyc", line 49, in update
  File "ManagedFile.pyc", line 84, in obtainFresh
ValueError: list.remove(x): x not in list

Traceback (most recent call last):
  File "Launcher.py", line 267, in UpdatePoll
  File "Launcher.py", line 132, in donePatching
  File "Launcher.py", line 142, in Request
  File "httplib.pyc", line 958, in request
  File "httplib.pyc", line 992, in _send_request
  File "httplib.pyc", line 954, in endheaders
  File "httplib.pyc", line 814, in _send_output
  File "httplib.pyc", line 776, in send
  File "httplib.pyc", line 1157, in connect
  File "socket.pyc", line 553, in create_connection
socket.gaierror: [Errno 11001] getaddrinfo failed
Exception in thread Patcher:
Traceback (most recent call last):
  File "threading.pyc", line 551, in __bootstrap_inner
  File "threading.pyc", line 504, in run
  File "Patcher.pyc", line 55, in Patch
  File "ManagedFile.pyc", line 49, in update
  File "ManagedFile.pyc", line 84, in obtainFresh
ValueError: list.remove(x): x not in list

Exception in thread Patcher:
Traceback (most recent call last):
  File "threading.pyc", line 551, in __bootstrap_inner
  File "threading.pyc", line 504, in run
  File "Patcher.pyc", line 55, in Patch
  File "ManagedFile.pyc", line 49, in update
  File "ManagedFile.pyc", line 84, in obtainFresh
ValueError: list.remove(x): x not in list

Traceback (most recent call last):
  File "Launcher.py", line 267, in UpdatePoll
  File "Launcher.py", line 132, in donePatching
  File "Launcher.py", line 142, in Request
  File "httplib.pyc", line 958, in request
  File "httplib.pyc", line 992, in _send_request
  File "httplib.pyc", line 954, in endheaders
  File "httplib.pyc", line 814, in _send_output
  File "httplib.pyc", line 776, in send
  File "httplib.pyc", line 1157, in connect
  File "socket.pyc", line 553, in create_connection
socket.gaierror: [Errno 11001] getaddrinfo failed
Traceback (most recent call last):
  File "Launcher.py", line 267, in UpdatePoll
  File "Launcher.py", line 132, in donePatching
  File "Launcher.py", line 142, in Request
  File "httplib.pyc", line 958, in request
  File "httplib.pyc", line 992, in _send_request
  File "httplib.pyc", line 954, in endheaders
  File "httplib.pyc", line 814, in _send_output
  File "httplib.pyc", line 776, in send
  File "httplib.pyc", line 1157, in connect
  File "socket.pyc", line 553, in create_connection
socket.gaierror: [Errno 11001] getaddrinfo failed
Traceback (most recent call last):
  File "Launcher.py", line 267, in UpdatePoll
  File "Launcher.py", line 132, in donePatching
  File "Launcher.py", line 142, in Request
  File "httplib.pyc", line 958, in request
  File "httplib.pyc", line 992, in _send_request
  File "httplib.pyc", line 954, in endheaders
  File "httplib.pyc", line 814, in _send_output
  File "httplib.pyc", line 776, in send
  File "httplib.pyc", line 1157, in connect
  File "socket.pyc", line 553, in create_connection
socket.gaierror: [Errno 11001] getaddrinfo failed
Traceback (most recent call last):
  File "Launcher.py", line 6, in <module>
  File "zipextimporter.pyc", line 82, in load_module
  File "Patcher.pyc", line 37, in <module>
d_module
  File "urllib2.pyc", line 126, in urlopen
  File "urllib2.pyc", line 400, in open
n
  File "urllib2.pyc", line 418, in _open
  File "urllib2.pyc", line 378, in _call_chain
  File "urllib2.pyc", line 1207, in http_open

  File "urllib2.pyc", line 1177, in do_open

  File "urllib2.pyc", line 1177, in do_open
urllib2.RLErrorURLError: rlopen error [Errno 11001] getaddrinfo failed><urlopen error [Errno 11001] getaddrinfo failed>
Traceback (most recent call last):
  File "Launcher.py", line 6, in <module>
  File "zipextimporter.pyc", line 82, in load_module
  File "Patcher.pyc", line 37, in <module>
  File "urllib2.pyc", line 126, in urlopen
  File "urllib2.pyc", line 400, in open
  File "urllib2.pyc", line 418, in _open
  File "urllib2.pyc", line 378, in _call_chain
  File "urllib2.pyc", line 1207, in http_open
  File "urllib2.pyc", line 1177, in do_open
urllib2.URLError: <urlopen error [Errno 11001] getaddrinfo failed>
Exception in thread Patcher:
Traceback (most recent call last):
  File "threading.pyc", line 551, in __bootstrap_inner
  File "threading.pyc", line 504, in run
  File "Patcher.pyc", line 55, in Patch
  File "ManagedFile.pyc", line 49, in update
  File "ManagedFile.pyc", line 84, in obtainFresh
ValueError: list.remove(x): x not in list

Exception in thread Patcher:
Traceback (most recent call last):
  File "threading.pyc", line 551, in __bootstrap_inner
  File "threading.pyc", line 504, in run
  File "Patcher.pyc", line 55, in Patch
  File "ManagedFile.pyc", line 49, in update
  File "ManagedFile.pyc", line 84, in obtainFresh
ValueError: list.remove(x): x not in list

Exception in thread Patcher:
Traceback (most recent call last):
  File "threading.pyc", line 551, in __bootstrap_inner
  File "threading.pyc", line 504, in run
  File "Patcher.pyc", line 55, in Patch
  File "ManagedFile.pyc", line 49, in update
  File "ManagedFile.pyc", line 84, in obtainFresh
ValueError: list.remove(x): x not in list

Traceback (most recent call last):
  File "Launcher.py", line 6, in <module>
  File "zipextimporter.pyc", line 82, in load_module
  File "Patcher.pyc", line 37, in <module>
d_module
  File "urllib2.pyc", line 126, in urlopen
  File "urllib2.pyc", line 400, in open
n
  File "urllib2.pyc", line 418, in _open
  File "urllib2.pyc", line 378, in _call_chain
  File "urllib2.pyc", line 1207, in http_open

  File "urllib2.pyc", line 1177, in do_open

urllib2"urllib2.pyc", line 1177, in do_open
.rllib2URLError: LError<urlopen error [Errno 11001] getaddrinfo failed>
rlopen error [Errno 11001] getaddrinfo failed>
Traceback (most recent call last):
  File "Launcher.py", line 6, in <module>
  File "zipextimporter.pyc", line 82, in load_module
  File "Patcher.pyc", line 37, in <module>
  File "urllib2.pyc", line 126, in urlopen
  File "urllib2.pyc", line 400, in open
  File "urllib2.pyc", line 418, in _open
  File "urllib2.pyc", line 378, in _call_chain
  File "urllib2.pyc", line 1207, in http_open
  File "urllib2.pyc", line 1177, in do_open
urllib2.URLError: <urlopen error [Errno 11001] getaddrinfo failed>
Traceback (most recent call last):
  File "Launcher.py", line 267, in UpdatePoll
  File "Launcher.py", line 132, in donePatching
  File "Launcher.py", line 142, in Request
  File "httplib.pyc", line 958, in request
  File "httplib.pyc", line 992, in _send_request
  File "httplib.pyc", line 954, in endheaders
  File "httplib.pyc", line 814, in _send_output
  File "httplib.pyc", line 776, in send
  File "httplib.pyc", line 1161, in connect
  File "ssl.pyc", line 381, in wrap_socket
  File "ssl.pyc", line 143, in __init__
  File "ssl.pyc", line 305, in do_handshake
ssl.SSLError: [Errno 1] _ssl.c:504: error:14077410:SSL routines:SSL23_GET_SERVER_HELLO:sslv3 alert handshake failure
